Workbook

Sheet Department_Reference
A1: Department Code | B1: Full Department Name | C1: Standard Base Cost ($) | D1: Department Manager
A2: CARD | B2: Cardiology | C2: 1800 | D2: R. Singh
A3: ER | B3: Emergency | C3: 850 | D3: T. Alvarez
A4: ORTH | B4: Orthopedics | C4: 1500 | D4: M. Chen
A5: PEDS | B5: Pediatrics | C5: 700 | D5: J. Okafor
A6: SURG | B6: General Surgery | C6: 3200 | D6: L. Romano

Sheet Daily_Staffing_Log
A1: Log Date | B1: Shift | C1: Shift Hours | D1: Staff on Duty | E1: Department Code
A2: 46023 | B2: Day | C2: 07:00-15:00 | D2: 6 | E2: ER
A3: 46023 | B3: Evening | C3: 15:00-23:00 | D3: 11 | E3: ER
A4: 46023 | B4: Night | C4: 23:00-07:00 | D4: 4 | E4: ER
A5: 46023 | B5: Day | C5: 07:00-15:00 | D5: 4 | E5: CARD
A6: 46023 | B6: Evening | C6: 15:00-23:00 | D6: 7 | E6: CARD
A7: 46023 | B7: Night | C7: 23:00-07:00 | D7: 1 | E7: CARD
A8: 46023 | B8: Day | C8: 07:00-15:00 | D8: 6 | E8: ORTH
A9: 46023 | B9: Evening | C9: 15:00-23:00 | D9: 7 | E9: ORTH
A10: 46023 | B10: Night | C10: 23:00-07:00 | D10: 1 | E10: ORTH
A11: 46023 | B11: Day | C11: 07:00-15:00 | D11: 8 | E11: PEDS
A12: 46023 | B12: Evening | C12: 15:00-23:00 | D12: 4 | E12: PEDS
A13: 46023 | B13: Night | C13: 23:00-07:00 | D13: 1 | E13: PEDS
... A1351: 46112 | B1351: Night | C1351: 23:00-07:00 | D1351: 4 | E1351: SURG

Sheet Patient_Satisfaction_Data
A1: Visit ID | B1: Visit Date | C1: Arrival Time | D1: Department Code | E1: Department Full Name | F1: Patient Name | G1: Age | H1: Gender | I1: Insurance | J1: Wait Time (min) | K1: Treatment Time (min) | L1: Satisfaction (1-5) | M1: Readmitted 30d | N1: Charge Amount | O1: Shift Type | P1: Staff on Duty
A2: 1001 | B2: 46023 | C2: 0.23055556 | D2: SURG | E2: General Surgery | F2: Patient 1001 | G2: 40 | H2: MALE | I2: Private | J2: 50 | K2: 83 | L2: 3.6 | M2: No | N2: 3390.98 | O2: =IF(EHR_Export[[#This Row],[Arrival Time]]<=TIME(7,0,0), "Night", IF(EHR_Export[[#This Row],[Arrival Time]]<TIME(15,0,0), "Day", "Evening")) -> Night | P2: {=_xlfn.XLOOKUP(1,(Daily_Staffing_Log[Log Date]=EHR_Export[[#This Row],[Visit Date]])*(Daily_Staffing_Log[Department Code]=EHR_Export[[#This Row],[Department Code]])*(Daily_Staffing_Log[Shift]=EHR_Export[[#This Row],[Shift Type]]),Daily_Staffing_Log[Staff on Duty],"Unknown")} -> 4
A3: 1006 | B3: 46023 | C3: 0.37986111 | D3: SURG | E3: General Surgery | F3: Patient 1006 | G3: 23 | H3: FEMALE | I3: Medicaid | J3: 55 | K3: 79 | L3: 3.5 | M3: No | N3: 3996.59 | O3: =IF(EHR_Export[[#This Row],[Arrival Time]]<=TIME(7,0,0), "Night", IF(EHR_Export[[#This Row],[Arrival Time]]<TIME(15,0,0), "Day", "Evening")) -> Day | P3: {=_xlfn.XLOOKUP(1,(Daily_Staffing_Log[Log Date]=EHR_Export[[#This Row],[Visit Date]])*(Daily_Staffing_Log[Department Code]=EHR_Export[[#This Row],[Department Code]])*(Daily_Staffing_Log[Shift]=EHR_Export[[#This Row],[Shift Type]]),Daily_Staffing_Log[Staff on Duty],"Unknown")} -> 7
A4: 1004 | B4: 46023 | C4: 0.92152778 | D4: CARD | E4: Cardiology | F4: Patient 1004 | G4: 36 | H4: MALE | I4: Private | J4: 29 | K4: 78 | M4: No | N4: 2343.67 | O4: =IF(EHR_Export[[#This Row],[Arrival Time]]<=TIME(7,0,0), "Night", IF(EHR_Export[[#This Row],[Arrival Time]]<TIME(15,0,0), "Day", "Evening")) -> Evening | P4: {=_xlfn.XLOOKUP(1,(Daily_Staffing_Log[Log Date]=EHR_Export[[#This Row],[Visit Date]])*(Daily_Staffing_Log[Department Code]=EHR_Export[[#This Row],[Department Code]])*(Daily_Staffing_Log[Shift]=EHR_Export[[#This Row],[Shift Type]]),Daily_Staffing_Log[Staff on Duty],"Unknown")} -> 7
A5: 1005 | B5: 46023 | C5: 0.80347222 | D5: PEDS | E5: Pediatrics | F5: Patient 1005 | G5: 35 | H5: FEMALE | I5: Private | J5: 23 | K5: 69 | L5: 4.3 | M5: No | N5: 620.4 | O5: =IF(EHR_Export[[#This Row],[Arrival Time]]<=TIME(7,0,0), "Night", IF(EHR_Export[[#This Row],[Arrival Time]]<TIME(15,0,0), "Day", "Evening")) -> Evening | P5: {=_xlfn.XLOOKUP(1,(Daily_Staffing_Log[Log Date]=EHR_Export[[#This Row],[Visit Date]])*(Daily_Staffing_Log[Department Code]=EHR_Export[[#This Row],[Department Code]])*(Daily_Staffing_Log[Shift]=EHR_Export[[#This Row],[Shift Type]]),Daily_Staffing_Log[Staff on Duty],"Unknown")} -> 4
A6: 1007 | B6: 46023 | C6: 0.725 | D6: CARD | E6: Cardiology | F6: Patient 1007 | G6: 63 | H6: FEMALE | I6: Medicaid | J6: 21 | K6: 46 | L6: 4.4 | M6: No | O6: =IF(EHR_Export[[#This Row],[Arrival Time]]<=TIME(7,0,0), "Night", IF(EHR_Export[[#This Row],[Arrival Time]]<TIME(15,0,0), "Day", "Evening")) -> Evening | P6: {=_xlfn.XLOOKUP(1,(Daily_Staffing_Log[Log Date]=EHR_Export[[#This Row],[Visit Date]])*(Daily_Staffing_Log[Department Code]=EHR_Export[[#This Row],[Department Code]])*(Daily_Staffing_Log[Shift]=EHR_Export[[#This Row],[Shift Type]]),Daily_Staffing_Log[Staff on Duty],"Unknown")} -> 7
A7: 1002 | B7: 46023 | C7: 0.91805556 | D7: ORTH | E7: Orthopedics | F7: Patient 1002 | G7: 34 | H7: FEMALE | I7: Private | J7: 74 | K7: 47 | L7: 2.8 | M7: No | N7: 2144.07 | O7: =IF(EHR_Export[[#This Row],[Arrival Time]]<=TIME(7,0,0), "Night", IF(EHR_Export[[#This Row],[Arrival Time]]<TIME(15,0,0), "Day", "Evening")) -> Evening | P7: {=_xlfn.XLOOKUP(1,(Daily_Staffing_Log[Log Date]=EHR_Export[[#This Row],[Visit Date]])*(Daily_Staffing_Log[Department Code]=EHR_Export[[#This Row],[Department Code]])*(Daily_Staffing_Log[Shift]=EHR_Export[[#This Row],[Shift Type]]),Daily_Staffing_Log[Staff on Duty],"Unknown")} -> 7
A8: 1003 | B8: 46023 | C8: 0.61736111 | D8: ER | E8: Emergency | F8: Patient 1003 | G8: 38 | H8: FEMALE | I8: Medicare | J8: 26 | K8: 56 | L8: 3.6 | M8: No | N8: 866.36 | O8: =IF(EHR_Export[[#This Row],[Arrival Time]]<=TIME(7,0,0), "Night", IF(EHR_Export[[#This Row],[Arrival Time]]<TIME(15,0,0), "Day", "Evening")) -> Day | P8: {=_xlfn.XLOOKUP(1,(Daily_Staffing_Log[Log Date]=EHR_Export[[#This Row],[Visit Date]])*(Daily_Staffing_Log[Department Code]=EHR_Export[[#This Row],[Department Code]])*(Daily_Staffing_Log[Shift]=EHR_Export[[#This Row],[Shift Type]]),Daily_Staffing_Log[Staff on Duty],"Unknown")} -> 6
A9: 1011 | B9: 46024 | C9: 0.32916667 | D9: ER | E9: Emergency | F9: Patient 1011 | G9: 76 | H9: FEMALE | I9: Medicaid | J9: 32 | K9: 55 | L9: 3.5 | M9: No | N9: 547.75 | O9: =IF(EHR_Export[[#This Row],[Arrival Time]]<=TIME(7,0,0), "Night", IF(EHR_Export[[#This Row],[Arrival Time]]<TIME(15,0,0), "Day", "Evening")) -> Day | P9: {=_xlfn.XLOOKUP(1,(Daily_Staffing_Log[Log Date]=EHR_Export[[#This Row],[Visit Date]])*(Daily_Staffing_Log[Department Code]=EHR_Export[[#This Row],[Department Code]])*(Daily_Staffing_Log[Shift]=EHR_Export[[#This Row],[Shift Type]]),Daily_Staffing_Log[Staff on Duty],"Unknown")} -> 6
A10: 1015 | B10: 46024 | C10: 0.88125 | D10: ER | E10: Emergency | F10: Patient 1015 | G10: 49 | H10: FEMALE | I10: Medicare | J10: 55 | K10: 49 | L10: 2.6 | M10: No | N10: 1249.89 | O10: =IF(EHR_Export[[#This Row],[Arrival Time]]<=TIME(7,0,0), "Night", IF(EHR_Export[[#This Row],[Arrival Time]]<TIME(15,0,0), "Day", "Evening")) -> Evening | P10: {=_xlfn.XLOOKUP(1,(Daily_Staffing_Log[Log Date]=EHR_Export[[#This Row],[Visit Date]])*(Daily_Staffing_Log[Department Code]=EHR_Export[[#This Row],[Department Code]])*(Daily_Staffing_Log[Shift]=EHR_Export[[#This Row],[Shift Type]]),Daily_Staffing_Log[Staff on Duty],"Unknown")} -> 8
A11: 1012 | B11: 46024 | C11: 0.75833333 | D11: PEDS | E11: Pediatrics | F11: Patient 1012 | G11: 44 | H11: FEMALE | I11: Medicare | J11: 45 | K11: 40 | L11: 3.5 | M11: No | N11: 833.24 | O11: =IF(EHR_Export[[#This Row],[Arrival Time]]<=TIME(7,0,0), "Night", IF(EHR_Export[[#This Row],[Arrival Time]]<TIME(15,0,0), "Day", "Evening")) -> Evening | P11: {=_xlfn.XLOOKUP(1,(Daily_Staffing_Log[Log Date]=EHR_Export[[#This Row],[Visit Date]])*(Daily_Staffing_Log[Department Code]=EHR_Export[[#This Row],[Department Code]])*(Daily_Staffing_Log[Shift]=EHR_Export[[#This Row],[Shift Type]]),Daily_Staffing_Log[Staff on Duty],"Unknown")} -> 7
A12: 1013 | B12: 46024 | C12: 0.38402778 | D12: SURG | E12: General Surgery | F12: Patient 1013 | G12: 65 | H12: FEMALE | I12: Uninsured | J12: 51 | K12: 121 | L12: 2.9 | M12: No | N12: 3303.34 | O12: =IF(EHR_Export[[#This Row],[Arrival Time]]<=TIME(7,0,0), "Night", IF(EHR_Export[[#This Row],[Arrival Time]]<TIME(15,0,0), "Day", "Evening")) -> Day | P12: {=_xlfn.XLOOKUP(1,(Daily_Staffing_Log[Log Date]=EHR_Export[[#This Row],[Visit Date]])*(Daily_Staffing_Log[Department Code]=EHR_Export[[#This Row],[Department Code]])*(Daily_Staffing_Log[Shift]=EHR_Export[[#This Row],[Shift Type]]),Daily_Staffing_Log[Staff on Duty],"Unknown")} -> 10
A13: 1009 | B13: 46024 | C13: 0.20833333 | D13: CARD | E13: Cardiology | F13: Patient 1009 | G13: 58 | H13: MALE | I13: Private | J13: 39 | K13: 66 | M13: No | N13: 1345.12 | O13: =IF(EHR_Export[[#This Row],[Arrival Time]]<=TIME(7,0,0), "Night", IF(EHR_Export[[#This Row],[Arrival Time]]<TIME(15,0,0), "Day", "Evening")) -> Night | P13: {=_xlfn.XLOOKUP(1,(Daily_Staffing_Log[Log Date]=EHR_Export[[#This Row],[Visit Date]])*(Daily_Staffing_Log[Department Code]=EHR_Export[[#This Row],[Department Code]])*(Daily_Staffing_Log[Shift]=EHR_Export[[#This Row],[Shift Type]]),Daily_Staffing_Log[Staff on Duty],"Unknown")} -> 5
A14: 1008 | B14: 46024 | C14: 0.61041667 | D14: CARD | E14: Cardiology | F14: Patient 1008 | G14: 35 | H14: FEMALE | I14: Medicaid | J14: 60 | K14: 10 | L14: 3.1 | M14: No | N14: 1277.9 | O14: =IF(EHR_Export[[#This Row],[Arrival Time]]<=TIME(7,0,0), "Night", IF(EHR_Export[[#This Row],[Arrival Time]]<TIME(15,0,0), "Day", "Evening")) -> Day | P14: {=_xlfn.XLOOKUP(1,(Daily_Staffing_Log[Log Date]=EHR_Export[[#This Row],[Visit Date]])*(Daily_Staffing_Log[Department Code]=EHR_Export[[#This Row],[Department Code]])*(Daily_Staffing_Log[Shift]=EHR_Export[[#This Row],[Shift Type]]),Daily_Staffing_Log[Staff on Duty],"Unknown")} -> 7
A15: 1010 | B15: 46024 | C15: 0.55486111 | D15: ORTH | E15: Orthopedics | F15: Patient 1010 | G15: 66 | H15: FEMALE | I15: Uninsured | J15: 49 | K15: 10 | L15: 2.7 | M15: No | N15: 1577.08 | O15: =IF(EHR_Export[[#This Row],[Arrival Time]]<=TIME(7,0,0), "Night", IF(EHR_Export[[#This Row],[Arrival Time]]<TIME(15,0,0), "Day", "Evening")) -> Day | P15: {=_xlfn.XLOOKUP(1,(Daily_Staffing_Log[Log Date]=EHR_Export[[#This Row],[Visit Date]])*(Daily_Staffing_Log[Department Code]=EHR_Export[[#This Row],[Department Code]])*(Daily_Staffing_Log[Shift]=EHR_Export[[#This Row],[Shift Type]]),Daily_Staffing_Log[Staff on Duty],"Unknown")} -> 4
A16: 1014 | B16: 46024 | C16: 0.76458333 | D16: SURG | E16: General Surgery | F16: Patient 1014 | G16: 36 | H16: FEMALE | I16: Uninsured | J16: 91 | K16: 86 | L16: 1.8 | M16: No | N16: 4325.31 | O16: =IF(EHR_Export[[#This Row],[Arrival Time]]<=TIME(7,0,0), "Night", IF(EHR_Export[[#This Row],[Arrival Time]]<TIME(15,0,0), "Day", "Evening")) -> Evening | P16: {=_xlfn.XLOOKUP(1,(Daily_Staffing_Log[Log Date]=EHR_Export[[#This Row],[Visit Date]])*(Daily_Staffing_Log[Department Code]=EHR_Export[[#This Row],[Department Code]])*(Daily_Staffing_Log[Shift]=EHR_Export[[#This Row],[Shift Type]]),Daily_Staffing_Log[Staff on Duty],"Unknown")} -> 4
A17: 1019 | B17: 46025 | C17: 0.84166667 | D17: CARD | E17: Cardiology | F17: Patient 1019 | G17: 28 | H17: MALE | I17: Private | J17: 60 | K17: 55 | M17: No | N17: 2400.16 | O17: =IF(EHR_Export[[#This Row],[Arrival Time]]<=TIME(7,0,0), "Night", IF(EHR_Export[[#This Row],[Arrival Time]]<TIME(15,0,0), "Day", "Evening")) -> Evening | P17: {=_xlfn.XLOOKUP(1,(Daily_Staffing_Log[Log Date]=EHR_Export[[#This Row],[Visit Date]])*(Daily_Staffing_Log[Department Code]=EHR_Export[[#This Row],[Department Code]])*(Daily_Staffing_Log[Shift]=EHR_Export[[#This Row],[Shift Type]]),Daily_Staffing_Log[Staff on Duty],"Unknown")} -> 3
A18: 1020 | B18: 46025 | C18: 0.51111111 | D18: SURG | E18: General Surgery | F18: Patient 1020 | G18: 59 | H18: FEMALE | I18: Medicare | J18: 75 | K18: 138 | L18: 2.6 | M18: No | N18: 3751.67 | O18: =IF(EHR_Export[[#This Row],[Arrival Time]]<=TIME(7,0,0), "Night", IF(EHR_Export[[#This Row],[Arrival Time]]<TIME(15,0,0), "Day", "Evening")) -> Day | P18: {=_xlfn.XLOOKUP(1,(Daily_Staffing_Log[Log Date]=EHR_Export[[#This Row],[Visit Date]])*(Daily_Staffing_Log[Department Code]=EHR_Export[[#This Row],[Department Code]])*(Daily_Staffing_Log[Shift]=EHR_Export[[#This Row],[Shift Type]]),Daily_Staffing_Log[Staff on Duty],"Unknown")} -> 10
A19: 1024 | B19: 46025 | C19: 0.71319444 | D19: SURG | E19: General Surgery | F19: Patient 1024 | G19: 50 | H19: MALE | I19: Private | J19: 110 | K19: 132 | L19: 2.1 | M19: No | N19: 2487.93 | O19: =IF(EHR_Export[[#This Row],[Arrival Time]]<=TIME(7,0,0), "Night", IF(EHR_Export[[#This Row],[Arrival Time]]<TIME(15,0,0), "Day", "Evening")) -> Evening | P19: {=_xlfn.XLOOKUP(1,(Daily_Staffing_Log[Log Date]=EHR_Export[[#This Row],[Visit Date]])*(Daily_Staffing_Log[Department Code]=EHR_Export[[#This Row],[Department Code]])*(Daily_Staffing_Log[Shift]=EHR_Export[[#This Row],[Shift Type]]),Daily_Staffing_Log[Staff on Duty],"Unknown")} -> 7
A20: 1017 | B20: 46025 | C20: 0.375 | D20: PEDS | E20: Pediatrics | F20: Patient 1017 | G20: 18 | H20: FEMALE | I20: Medicaid | J20: 33 | K20: 10 | L20: 4 | M20: No | N20: 478.65 | O20: =IF(EHR_Export[[#This Row],[Arrival Time]]<=TIME(7,0,0), "Night", IF(EHR_Export[[#This Row],[Arrival Time]]<TIME(15,0,0), "Day", "Evening")) -> Day | P20: {=_xlfn.XLOOKUP(1,(Daily_Staffing_Log[Log Date]=EHR_Export[[#This Row],[Visit Date]])*(Daily_Staffing_Log[Department Code]=EHR_Export[[#This Row],[Department Code]])*(Daily_Staffing_Log[Shift]=EHR_Export[[#This Row],[Shift Type]]),Daily_Staffing_Log[Staff on Duty],"Unknown")} -> 7
A21: 1028 | B21: 46025 | C21: 0.26180556 | D21: ER | E21: Emergency | F21: Patient 1028 | G21: 40 | H21: MALE | I21: Uninsured | J21: 57 | K21: 31 | L21: 3.6 | M21: No | N21: 741.91 | O21: =IF(EHR_Export[[#This Row],[Arrival Time]]<=TIME(7,0,0), "Night", IF(EHR_Export[[#This Row],[Arrival Time]]<TIME(15,0,0), "Day", "Evening")) -> Night | P21: {=_xlfn.XLOOKUP(1,(Daily_Staffing_Log[Log Date]=EHR_Export[[#This Row],[Visit Date]])*(Daily_Staffing_Log[Department Code]=EHR_Export[[#This Row],[Department Code]])*(Daily_Staffing_Log[Shift]=EHR_Export[[#This Row],[Shift Type]]),Daily_Staffing_Log[Staff on Duty],"Unknown")} -> 5
A22: 1027 | B22: 46025 | C22: 0.47847222 | D22: ER | E22: Emergency | F22: Patient 1027 | G22: 67 | H22: FEMALE | I22: Medicare | J22: 40 | K22: 25 | L22: 3.9 | M22: No | N22: 697.8 | O22: =IF(EHR_Export[[#This Row],[Arrival Time]]<=TIME(7,0,0), "Night", IF(EHR_Export[[#This Row],[Arrival Time]]<TIME(15,0,0), "Day", "Evening")) -> Day | P22: {=_xlfn.XLOOKUP(1,(Daily_Staffing_Log[Log Date]=EHR_Export[[#This Row],[Visit Date]])*(Daily_Staffing_Log[Department Code]=EHR_Export[[#This Row],[Department Code]])*(Daily_Staffing_Log[Shift]=EHR_Export[[#This Row],[Shift Type]]),Daily_Staffing_Log[Staff on Duty],"Unknown")} -> 8
A23: 1029 | B23: 46025 | C23: 0.77638889 | D23: ORTH | E23: Orthopedics | F23: Patient 1029 | G23: 21 | H23: FEMALE | I23: Medicare | J23: 78 | K23: 35 | L23: 2.4 | M23: No | N23: 1929.89 | O23: =IF(EHR_Export[[#This Row],[Arrival Time]]<=TIME(7,0,0), "Night", IF(EHR_Export[[#This Row],[Arrival Time]]<TIME(15,0,0), "Day", "Evening")) -> Evening | P23: {=_xlfn.XLOOKUP(1,(Daily_Staffing_Log[Log Date]=EHR_Export[[#This Row],[Visit Date]])*(Daily_Staffing_Log[Department Code]=EHR_Export[[#This Row],[Department Code]])*(Daily_Staffing_Log[Shift]=EHR_Export[[#This Row],[Shift Type]]),Daily_Staffing_Log[Staff on Duty],"Unknown")} -> 6
A24: 1025 | B24: 46025 | C24: 0.93888889 | D24: ER | E24: Emergency | F24: Patient 1025 | G24: 51 | H24: MALE | I24: Private | J24: 78 | K24: 12 | L24: 3.4 | M24: No | N24: 423.08 | O24: =IF(EHR_Export[[#This Row],[Arrival Time]]<=TIME(7,0,0), "Night", IF(EHR_Export[[#This Row],[Arrival Time]]<TIME(15,0,0), "Day", "Evening")) -> Evening | P24: {=_xlfn.XLOOKUP(1,(Daily_Staffing_Log[Log Date]=EHR_Export[[#This Row],[Visit Date]])*(Daily_Staffing_Log[Department Code]=EHR_Export[[#This Row],[Department Code]])*(Daily_Staffing_Log[Shift]=EHR_Export[[#This Row],[Shift Type]]),Daily_Staffing_Log[Staff on Duty],"Unknown")} -> 8
A25: 1022 | B25: 46025 | C25: 0.84097222 | D25: SURG | E25: General Surgery | F25: Patient 1022 | G25: 70 | H25: MALE | I25: Private | J25: 108 | K25: 54 | L25: 2 | M25: No | N25: 1472.45 | O25: =IF(EHR_Export[[#This Row],[Arrival Time]]<=TIME(7,0,0), "Night", IF(EHR_Export[[#This Row],[Arrival Time]]<TIME(15,0,0), "Day", "Evening")) -> Evening | P25: {=_xlfn.XLOOKUP(1,(Daily_Staffing_Log[Log Date]=EHR_Export[[#This Row],[Visit Date]])*(Daily_Staffing_Log[Department Code]=EHR_Export[[#This Row],[Department Code]])*(Daily_Staffing_Log[Shift]=EHR_Export[[#This Row],[Shift Type]]),Daily_Staffing_Log[Staff on Duty],"Unknown")} -> 7
A26: 1026 | B26: 46025 | C26: 0.82291667 | D26: ER | E26: Emergency | F26: Patient 1026 | G26: 31 | H26: MALE | I26: Medicare | J26: 75 | K26: 45 | L26: 3.3 | M26: No | N26: 909.27 | O26: =IF(EHR_Export[[#This Row],[Arrival Time]]<=TIME(7,0,0), "Night", IF(EHR_Export[[#This Row],[Arrival Time]]<TIME(15,0,0), "Day", "Evening")) -> Evening | P26: {=_xlfn.XLOOKUP(1,(Daily_Staffing_Log[Log Date]=EHR_Export[[#This Row],[Visit Date]])*(Daily_Staffing_Log[Department Code]=EHR_Export[[#This Row],[Department Code]])*(Daily_Staffing_Log[Shift]=EHR_Export[[#This Row],[Shift Type]]),Daily_Staffing_Log[Staff on Duty],"Unknown")} -> 8
A27: 1016 | B27: 46025 | C27: 0.76388889 | D27: ER | E27: Emergency | F27: Patient 1016 | G27: 94 | H27: MALE | I27: Medicare | J27: 81 | K27: 33 | L27: 3 | M27: No | N27: 397.15 | O27: =IF(EHR_Export[[#This Row],[Arrival Time]]<=TIME(7,0,0), "Night", IF(EHR_Export[[#This Row],[Arrival Time]]<TIME(15,0,0), "Day", "Evening")) -> Evening | P27: {=_xlfn.XLOOKUP(1,(Daily_Staffing_Log[Log Date]=EHR_Export[[#This Row],[Visit Date]])*(Daily_Staffing_Log[Department Code]=EHR_Export[[#This Row],[Department Code]])*(Daily_Staffing_Log[Shift]=EHR_Export[[#This Row],[Shift Type]]),Daily_Staffing_Log[Staff on Duty],"Unknown")} -> 8
A28: 1023 | B28: 46025 | C28: 0.41736111 | D28: CARD | E28: Cardiology | F28: Patient 1023 | G28: 51 | H28: FEMALE | I28: Private | J28: 46 | K28: 74 | M28: Yes | N28: 1407.57 | O28: =IF(EHR_Export[[#This Row],[Arrival Time]]<=TIME(7,0,0), "Night", IF(EHR_Export[[#This Row],[Arrival Time]]<TIME(15,0,0), "Day", "Evening")) -> Day | P28: {=_xlfn.XLOOKUP(1,(Daily_Staffing_Log[Log Date]=EHR_Export[[#This Row],[Visit Date]])*(Daily_Staffing_Log[Department Code]=EHR_Export[[#This Row],[Department Code]])*(Daily_Staffing_Log[Shift]=EHR_Export[[#This Row],[Shift Type]]),Daily_Staffing_Log[Staff on Duty],"Unknown")} -> 6
A29: 1021 | B29: 46025 | C29: 0.10763889 | D29: CARD | E29: Cardiology | F29: Patient 1021 | G29: 37 | H29: FEMALE | I29: Medicaid | J29: 52 | K29: 57 | L29: 3.6 | M29: No | N29: 3000.01 | O29: =IF(EHR_Export[[#This Row],[Arrival Time]]<=TIME(7,0,0), "Night", IF(EHR_Export[[#This Row],[Arrival Time]]<TIME(15,0,0), "Day", "Evening")) -> Night | P29: {=_xlfn.XLOOKUP(1,(Daily_Staffing_Log[Log Date]=EHR_Export[[#This Row],[Visit Date]])*(Daily_Staffing_Log[Department Code]=EHR_Export[[#This Row],[Department Code]])*(Daily_Staffing_Log[Shift]=EHR_Export[[#This Row],[Shift Type]]),Daily_Staffing_Log[Staff on Duty],"Unknown")} -> 4
A30: 1018 | B30: 46025 | C30: 0.17083333 | D30: ER | E30: Emergency | F30: Patient 1018 | G30: 41 | H30: FEMALE | I30: Medicaid | J30: 58 | K30: 10 | L30: 2.7 | M30: No | N30: 952.15 | O30: =IF(EHR_Export[[#This Row],[Arrival Time]]<=TIME(7,0,0), "Night", IF(EHR_Export[[#This Row],[Arrival Time]]<TIME(15,0,0), "Day", "Evening")) -> Night | P30: {=_xlfn.XLOOKUP(1,(Daily_Staffing_Log[Log Date]=EHR_Export[[#This Row],[Visit Date]])*(Daily_Staffing_Log[Department Code]=EHR_Export[[#This Row],[Department Code]])*(Daily_Staffing_Log[Shift]=EHR_Export[[#This Row],[Shift Type]]),Daily_Staffing_Log[Staff on Duty],"Unknown")} -> 5
A31: 1037 | B31: 46026 | C31: 0.32847222 | D31: SURG | E31: General Surgery | F31: Patient 1037 | G31: 30 | H31: MALE | I31: Medicaid | J31: 80 | K31: 121 | L31: 4.4 | M31: No | N31: 3403.65 | O31: =IF(EHR_Export[[#This Row],[Arrival Time]]<=TIME(7,0,0), "Night", IF(EHR_Export[[#This Row],[Arrival Time]]<TIME(15,0,0), "Day", "Evening")) -> Day | P31: {=_xlfn.XLOOKUP(1,(Daily_Staffing_Log[Log Date]=EHR_Export[[#This Row],[Visit Date]])*(Daily_Staffing_Log[Department Code]=EHR_Export[[#This Row],[Department Code]])*(Daily_Staffing_Log[Shift]=EHR_Export[[#This Row],[Shift Type]]),Daily_Staffing_Log[Staff on Duty],"Unknown")} -> 10
A32: 1038 | B32: 46026 | C32: 0.37847222 | D32: ER | E32: Emergency | F32: Patient 1038 | G32: 6 | H32: MALE | I32: Private | J32: 38 | K32: 54 | L32: 4.5 | M32: No | N32: 1177.96 | O32: =IF(EHR_Export[[#This Row],[Arrival Time]]<=TIME(7,0,0), "Night", IF(EHR_Export[[#This Row],[Arrival Time]]<TIME(15,0,0), "Day", "Evening")) -> Day | P32: {=_xlfn.XLOOKUP(1,(Daily_Staffing_Log[Log Date]=EHR_Export[[#This Row],[Visit Date]])*(Daily_Staffing_Log[Department Code]=EHR_Export[[#This Row],[Department Code]])*(Daily_Staffing_Log[Shift]=EHR_Export[[#This Row],[Shift Type]]),Daily_Staffing_Log[Staff on Duty],"Unknown")} -> 4
A33: 1032 | B33: 46026 | C33: 0.75972222 | D33: CARD | E33: Cardiology | F33: Patient 1032 | G33: 59 | H33: FEMALE | I33: Medicare | J33: 48 | K33: 55 | L33: 3.2 | M33: No | N33: 1097.63 | O33: =IF(EHR_Export[[#This Row],[Arrival Time]]<=TIME(7,0,0), "Night", IF(EHR_Export[[#This Row],[Arrival Time]]<TIME(15,0,0), "Day", "Evening")) -> Evening | P33: {=_xlfn.XLOOKUP(1,(Daily_Staffing_Log[Log Date]=EHR_Export[[#This Row],[Visit Date]])*(Daily_Staffing_Log[Department Code]=EHR_Export[[#This Row],[Department Code]])*(Daily_Staffing_Log[Shift]=EHR_Export[[#This Row],[Shift Type]]),Daily_Staffing_Log[Staff on Duty],"Unknown")} -> 2
A34: 1033 | B34: 46026 | C34: 0.56319444 | D34: ER | E34: Emergency | F34: Patient 1033 | G34: 25 | H34: FEMALE | I34: Private | J34: 37 | K34: 51 | L34: 4 | M34: No | N34: 797.29 | O34: =IF(EHR_Export[[#This Row],[Arrival Time]]<=TIME(7,0,0), "Night", IF(EHR_Export[[#This Row],[Arrival Time]]<TIME(15,0,0), "Day", "Evening")) -> Day | P34: {=_xlfn.XLOOKUP(1,(Daily_Staffing_Log[Log Date]=EHR_Export[[#This Row],[Visit Date]])*(Daily_Staffing_Log[Department Code]=EHR_Export[[#This Row],[Department Code]])*(Daily_Staffing_Log[Shift]=EHR_Export[[#This Row],[Shift Type]]),Daily_Staffing_Log[Staff on Duty],"Unknown")} -> 4
A35: 1041 | B35: 46026 | C35: 0.47430556 | D35: CARD | E35: Cardiology | F35: Patient 1041 | G35: 44 | H35: MALE | I35: Uninsured | J35: 33 | K35: 10 | L35: 3.6 | M35: No | N35: 2153.38 | O35: =IF(EHR_Export[[#This Row],[Arrival Time]]<=TIME(7,0,0), "Night", IF(EHR_Export[[#This Row],[Arrival Time]]<TIME(15,0,0), "Day", "Evening")) -> Day | P35: {=_xlfn.XLOOKUP(1,(Daily_Staffing_Log[Log Date]=EHR_Export[[#This Row],[Visit Date]])*(Daily_Staffing_Log[Department Code]=EHR_Export[[#This Row],[Department Code]])*(Daily_Staffing_Log[Shift]=EHR_Export[[#This Row],[Shift Type]]),Daily_Staffing_Log[Staff on Duty],"Unknown")} -> 7
A36: 1031 | B36: 46026 | C36: 0.59375 | D36: ER | E36: Emergency | F36: Patient 1031 | G36: 27 | H36: MALE | I36: Medicare | J36: 67 | K36: 32 | L36: 3.4 | M36: No | N36: 1067.52 | O36: =IF(EHR_Export[[#This Row],[Arrival Time]]<=TIME(7,0,0), "Night", IF(EHR_Export[[#This Row],[Arrival Time]]<TIME(15,0,0), "Day", "Evening")) -> Day | P36: {=_xlfn.XLOOKUP(1,(Daily_Staffing_Log[Log Date]=EHR_Export[[#This Row],[Visit Date]])*(Daily_Staffing_Log[Department Code]=EHR_Export[[#This Row],[Department Code]])*(Daily_Staffing_Log[Shift]=EHR_Export[[#This Row],[Shift Type]]),Daily_Staffing_Log[Staff on Duty],"Unknown")} -> 4
A37: 1035 | B37: 46026 | C37: 0.46319444 | D37: ER | E37: Emergency | F37: Patient 1035 | G37: 43 | H37: FEMALE | I37: Private | J37: 70 | K37: 58 | M37: Yes | N37: 617.69 | O37: =IF(EHR_Export[[#This Row],[Arrival Time]]<=TIME(7,0,0), "Night", IF(EHR_Export[[#This Row],[Arrival Time]]<TIME(15,0,0), "Day", "Evening")) -> Day | P37: {=_xlfn.XLOOKUP(1,(Daily_Staffing_Log[Log Date]=EHR_Export[[#This Row],[Visit Date]])*(Daily_Staffing_Log[Department Code]=EHR_Export[[#This Row],[Department Code]])*(Daily_Staffing_Log[Shift]=EHR_Export[[#This Row],[Shift Type]]),Daily_Staffing_Log[Staff on Duty],"Unknown")} -> 4
A38: 1030 | B38: 46026 | C38: 0.82708333 | D38: ORTH | E38: Orthopedics | F38: Patient 1030 | G38: 77 | H38: MALE | I38: Private | J38: 60 | K38: 18 | L38: 3 | M38: Yes | N38: 973.93 | O38: =IF(EHR_Export[[#This Row],[Arrival Time]]<=TIME(7,0,0), "Night", IF(EHR_Export[[#This Row],[Arrival Time]]<TIME(15,0,0), "Day", "Evening")) -> Evening | P38: {=_xlfn.XLOOKUP(1,(Daily_Staffing_Log[Log Date]=EHR_Export[[#This Row],[Visit Date]])*(Daily_Staffing_Log[Department Code]=EHR_Export[[#This Row],[Department Code]])*(Daily_Staffing_Log[Shift]=EHR_Export[[#This Row],[Shift Type]]),Daily_Staffing_Log[Staff on Duty],"Unknown")} -> 5
A39: 1034 | B39: 46026 | C39: 0.10347222 | D39: SURG | E39: General Surgery | F39: Patient 1034 | G39: 69 | H39: MALE | I39: Uninsured | J39: 84 | K39: 85 | L39: 3 | M39: No | N39: 3745.29 | O39: =IF(EHR_Export[[#This Row],[Arrival Time]]<=TIME(7,0,0), "Night", IF(EHR_Export[[#This Row],[Arrival Time]]<TIME(15,0,0), "Day", "Evening")) -> Night | P39: {=_xlfn.XLOOKUP(1,(Daily_Staffing_Log[Log Date]=EHR_Export[[#This Row],[Visit Date]])*(Daily_Staffing_Log[Department Code]=EHR_Export[[#This Row],[Department Code]])*(Daily_Staffing_Log[Shift]=EHR_Export[[#This Row],[Shift Type]]),Daily_Staffing_Log[Staff on Duty],"Unknown")} -> 2
A40: 1036 | B40: 46026 | C40: 0.47222222 | D40: ER | E40: Emergency | F40: Patient 1036 | G40: 46 | H40: MALE | I40: Medicaid | J40: 81 | K40: 71 | L40: 2.8 | M40: No | N40: 404.72 | O40: =IF(EHR_Export[[#This Row],[Arrival Time]]<=TIME(7,0,0), "Night", IF(EHR_Export[[#This Row],[Arrival Time]]<TIME(15,0,0), "Day", "Evening")) -> Day | P40: {=_xlfn.XLOOKUP(1,(Daily_Staffing_Log[Log Date]=EHR_Export[[#This Row],[Visit Date]])*(Daily_Staffing_Log[Department Code]=EHR_Export[[#This Row],[Department Code]])*(Daily_Staffing_Log[Shift]=EHR_Export[[#This Row],[Shift Type]]),Daily_Staffing_Log[Staff on Duty],"Unknown")} -> 4
...

Sheet Dashboard_Calculator
A1: Department | B1: Avg Wait Time (min) | C1: Avg Treatment Time (min) | D1: Avg Satisfaction | E1: vs. 3.8 Target | F1: Avg Charge | G1: Base Cost | H1: vs Base Cost | I1: Readmission Rate | J1: Wait Time | K1: Department | L1: Day | M1: Evening | N1: Night
A2: Cardiology | B2: =AVERAGEIF(EHR_Export[Department Full Name], Dashboard_Calculator!A2, EHR_Export[Wait Time (min)]) -> 42.856 | C2: =AVERAGEIF(EHR_Export[Department Full Name],Dashboard_Calculator!A2,EHR_Export[Treatment Time (min)]) -> 43.616 | D2: =AVERAGEIF(EHR_Export[Department Full Name],Dashboard_Calculator!A2,EHR_Export[Satisfaction (1-5)]) -> 3.6214953 | E2: =D2-3.8 -> -0.17850467 | F2: =AVERAGEIFS(EHR_Export[Charge Amount],EHR_Export[Department Full Name],A2,EHR_Export[Charge Amount],"<>") -> 1763.0102 | G2: =_xlfn.XLOOKUP(Dashboard_Calculator!A2,Dept_Reference[Full Department Name],Dept_Reference[Standard Base Cost ($)]) -> 1800 | H2: =F2-G2 -> -36.989836 | I2: =COUNTIFS(EHR_Export[Department Full Name],Dashboard_Calculator!A2,EHR_Export[Readmitted 30d],"Yes")/COUNTIF(EHR_Export[Department Full Name],Dashboard_Calculator!A2) -> 0.088 | K2: Cardiology | L2: =AVERAGEIFS(EHR_Export[Wait Time (min)],EHR_Export[Department Full Name],Dashboard_Calculator!K2,EHR_Export[Shift Type],Dashboard_Calculator!L$1) -> 37.942308 | M2: =AVERAGEIFS(EHR_Export[Wait Time (min)],EHR_Export[Department Full Name],Dashboard_Calculator!K2,EHR_Export[Shift Type],M$1) -> 48.209677 | N2: =AVERAGEIFS(EHR_Export[Wait Time (min)],EHR_Export[Department Full Name],Dashboard_Calculator!K2,EHR_Export[Shift Type],N$1) -> 35.909091
A3: Emergency | B3: =AVERAGEIF(EHR_Export[Department Full Name], Dashboard_Calculator!A3, EHR_Export[Wait Time (min)]) -> 55.215873 | C3: =AVERAGEIF(EHR_Export[Department Full Name],Dashboard_Calculator!A3,EHR_Export[Treatment Time (min)]) -> 39.793651 | D3: =AVERAGEIF(EHR_Export[Department Full Name],Dashboard_Calculator!A3,EHR_Export[Satisfaction (1-5)]) -> 3.4729825 | E3: =D3-3.8 -> -0.32701754 | F3: =AVERAGEIFS(EHR_Export[Charge Amount],EHR_Export[Department Full Name],A3,EHR_Export[Charge Amount],"<>") -> 852.69323 | G3: =_xlfn.XLOOKUP(Dashboard_Calculator!A3,Dept_Reference[Full Department Name],Dept_Reference[Standard Base Cost ($)]) -> 850 | H3: =F3-G3 -> 2.6932258 | I3: =COUNTIFS(EHR_Export[Department Full Name],Dashboard_Calculator!A3,EHR_Export[Readmitted 30d],"Yes")/COUNTIF(EHR_Export[Department Full Name],Dashboard_Calculator!A3) -> 0.088888889 | K3: Emergency | L3: =AVERAGEIFS(EHR_Export[Wait Time (min)],EHR_Export[Department Full Name],Dashboard_Calculator!K3,EHR_Export[Shift Type],Dashboard_Calculator!L$1) -> 48.307692 | M3: =AVERAGEIFS(EHR_Export[Wait Time (min)],EHR_Export[Department Full Name],Dashboard_Calculator!K3,EHR_Export[Shift Type],M$1) -> 62.758389 | N3: =AVERAGEIFS(EHR_Export[Wait Time (min)],EHR_Export[Department Full Name],Dashboard_Calculator!K3,EHR_Export[Shift Type],N$1) -> 49.304348
A4: General Surgery | B4: =AVERAGEIF(EHR_Export[Department Full Name], Dashboard_Calculator!A4, EHR_Export[Wait Time (min)]) -> 69.574803 | C4: =AVERAGEIF(EHR_Export[Department Full Name],Dashboard_Calculator!A4,EHR_Export[Treatment Time (min)]) -> 89.401575 | D4: =AVERAGEIF(EHR_Export[Department Full Name],Dashboard_Calculator!A4,EHR_Export[Satisfaction (1-5)]) -> 3.2139344 | E4: =D4-3.8 -> -0.58606557 | F4: =AVERAGEIFS(EHR_Export[Charge Amount],EHR_Export[Department Full Name],A4,EHR_Export[Charge Amount],"<>") -> 3239.2171 | G4: =_xlfn.XLOOKUP(Dashboard_Calculator!A4,Dept_Reference[Full Department Name],Dept_Reference[Standard Base Cost ($)]) -> 3200 | H4: =F4-G4 -> 39.21712 | I4: =COUNTIFS(EHR_Export[Department Full Name],Dashboard_Calculator!A4,EHR_Export[Readmitted 30d],"Yes")/COUNTIF(EHR_Export[Department Full Name],Dashboard_Calculator!A4) -> 0.11023622 | K4: General Surgery | L4: =AVERAGEIFS(EHR_Export[Wait Time (min)],EHR_Export[Department Full Name],Dashboard_Calculator!K4,EHR_Export[Shift Type],Dashboard_Calculator!L$1) -> 58.431034 | M4: =AVERAGEIFS(EHR_Export[Wait Time (min)],EHR_Export[Department Full Name],Dashboard_Calculator!K4,EHR_Export[Shift Type],M$1) -> 81.40678 | N4: =AVERAGEIFS(EHR_Export[Wait Time (min)],EHR_Export[Department Full Name],Dashboard_Calculator!K4,EHR_Export[Shift Type],N$1) -> 64.4
A5: Orthopedics | B5: =AVERAGEIF(EHR_Export[Department Full Name], Dashboard_Calculator!A5, EHR_Export[Wait Time (min)]) -> 64.09009 | C5: =AVERAGEIF(EHR_Export[Department Full Name],Dashboard_Calculator!A5,EHR_Export[Treatment Time (min)]) -> 40.252252 | D5: =AVERAGEIF(EHR_Export[Department Full Name],Dashboard_Calculator!A5,EHR_Export[Satisfaction (1-5)]) -> 3.3056604 | E5: =D5-3.8 -> -0.49433962 | F5: =AVERAGEIFS(EHR_Export[Charge Amount],EHR_Export[Department Full Name],A5,EHR_Export[Charge Amount],"<>") -> 1507.6381 | G5: =_xlfn.XLOOKUP(Dashboard_Calculator!A5,Dept_Reference[Full Department Name],Dept_Reference[Standard Base Cost ($)]) -> 1500 | H5: =F5-G5 -> 7.6381481 | I5: =COUNTIFS(EHR_Export[Department Full Name],Dashboard_Calculator!A5,EHR_Export[Readmitted 30d],"Yes")/COUNTIF(EHR_Export[Department Full Name],Dashboard_Calculator!A5) -> 0.09009009 | K5: Orthopedics | L5: =AVERAGEIFS(EHR_Export[Wait Time (min)],EHR_Export[Department Full Name],Dashboard_Calculator!K5,EHR_Export[Shift Type],Dashboard_Calculator!L$1) -> 52.521739 | M5: =AVERAGEIFS(EHR_Export[Wait Time (min)],EHR_Export[Department Full Name],Dashboard_Calculator!K5,EHR_Export[Shift Type],M$1) -> 76.351852 | N5: =AVERAGEIFS(EHR_Export[Wait Time (min)],EHR_Export[Department Full Name],Dashboard_Calculator!K5,EHR_Export[Shift Type],N$1) -> 52.272727
A6: Pediatrics | B6: =AVERAGEIF(EHR_Export[Department Full Name], Dashboard_Calculator!A6, EHR_Export[Wait Time (min)]) -> 38.333333 | C6: =AVERAGEIF(EHR_Export[Department Full Name],Dashboard_Calculator!A6,EHR_Export[Treatment Time (min)]) -> 40.963768 | D6: =AVERAGEIF(EHR_Export[Department Full Name],Dashboard_Calculator!A6,EHR_Export[Satisfaction (1-5)]) -> 3.7697674 | E6: =D6-3.8 -> -0.030232558 | F6: =AVERAGEIFS(EHR_Export[Charge Amount],EHR_Export[Department Full Name],A6,EHR_Export[Charge Amount],"<>") -> 697.87679 | G6: =_xlfn.XLOOKUP(Dashboard_Calculator!A6,Dept_Reference[Full Department Name],Dept_Reference[Standard Base Cost ($)]) -> 700 | H6: =F6-G6 -> -2.1232117 | I6: =COUNTIFS(EHR_Export[Department Full Name],Dashboard_Calculator!A6,EHR_Export[Readmitted 30d],"Yes")/COUNTIF(EHR_Export[Department Full Name],Dashboard_Calculator!A6) -> 0.12318841 | K6: Pediatrics | L6: =AVERAGEIFS(EHR_Export[Wait Time (min)],EHR_Export[Department Full Name],Dashboard_Calculator!K6,EHR_Export[Shift Type],Dashboard_Calculator!L$1) -> 33.824561 | M6: =AVERAGEIFS(EHR_Export[Wait Time (min)],EHR_Export[Department Full Name],Dashboard_Calculator!K6,EHR_Export[Shift Type],M$1) -> 43.149254 | N6: =AVERAGEIFS(EHR_Export[Wait Time (min)],EHR_Export[Department Full Name],Dashboard_Calculator!K6,EHR_Export[Shift Type],N$1) -> 33.642857
J8: Staffing | K8: Department | L8: Day | M8: Evening | N8: Night
K9: Cardiology | L9: =AVERAGEIFS(EHR_Export[Staff on Duty],EHR_Export[Department Full Name],Dashboard_Calculator!K9,EHR_Export[Shift Type],Dashboard_Calculator!L$8) -> 5.6923077 | M9: =AVERAGEIFS(EHR_Export[Staff on Duty],EHR_Export[Department Full Name],Dashboard_Calculator!K9,EHR_Export[Shift Type],Dashboard_Calculator!M$8) -> 4.8870968 | N9: =AVERAGEIFS(EHR_Export[Staff on Duty],EHR_Export[Department Full Name],Dashboard_Calculator!K9,EHR_Export[Shift Type],N$8) -> 3.5454545
A10: Overall Avg Satisfaction | B10: =AVERAGE(EHR_Export[Satisfaction (1-5)]) -> 3.4794393 | K10: Emergency | L10: =AVERAGEIFS(EHR_Export[Staff on Duty],EHR_Export[Department Full Name],Dashboard_Calculator!K10,EHR_Export[Shift Type],Dashboard_Calculator!L$8) -> 6.3706294 | M10: =AVERAGEIFS(EHR_Export[Staff on Duty],EHR_Export[Department Full Name],Dashboard_Calculator!K10,EHR_Export[Shift Type],Dashboard_Calculator!M$8) -> 9.5033557 | N10: =AVERAGEIFS(EHR_Export[Staff on Duty],EHR_Export[Department Full Name],Dashboard_Calculator!K10,EHR_Export[Shift Type],N$8) -> 5.2608696
A11: Overall Avg Wait time (min) | B11: =AVERAGE(EHR_Export[Wait Time (min)]) -> 53.909314 | K11: General Surgery | L11: =AVERAGEIFS(EHR_Export[Staff on Duty],EHR_Export[Department Full Name],Dashboard_Calculator!K11,EHR_Export[Shift Type],Dashboard_Calculator!L$8) -> 8.8275862 | M11: =AVERAGEIFS(EHR_Export[Staff on Duty],EHR_Export[Department Full Name],Dashboard_Calculator!K11,EHR_Export[Shift Type],Dashboard_Calculator!M$8) -> 5.5932203 | N11: =AVERAGEIFS(EHR_Export[Staff on Duty],EHR_Export[Department Full Name],Dashboard_Calculator!K11,EHR_Export[Shift Type],N$8) -> 2.3
A12: Overall Readmission Rate | B12: =COUNTIF(EHR_Export[Readmitted 30d], "Yes")/COUNTA(EHR_Export[Readmitted 30d]) -> 0.10075567 | K12: Orthopedics | L12: =AVERAGEIFS(EHR_Export[Staff on Duty],EHR_Export[Department Full Name],Dashboard_Calculator!K12,EHR_Export[Shift Type],Dashboard_Calculator!L$8) -> 5.1956522 | M12: =AVERAGEIFS(EHR_Export[Staff on Duty],EHR_Export[Department Full Name],Dashboard_Calculator!K12,EHR_Export[Shift Type],Dashboard_Calculator!M$8) -> 5 | N12: =AVERAGEIFS(EHR_Export[Staff on Duty],EHR_Export[Department Full Name],Dashboard_Calculator!K12,EHR_Export[Shift Type],N$8) -> 2.6363636
A13: Avg Charge vs Base | B13: =AVERAGE(H2:H6) -> 2.0870892 | K13: Pediatrics | L13: =AVERAGEIFS(EHR_Export[Staff on Duty],EHR_Export[Department Full Name],Dashboard_Calculator!K13,EHR_Export[Shift Type],Dashboard_Calculator!L$8) -> 5.7719298 | M13: =AVERAGEIFS(EHR_Export[Staff on Duty],EHR_Export[Department Full Name],Dashboard_Calculator!K13,EHR_Export[Shift Type],Dashboard_Calculator!M$8) -> 4.5373134 | N13: =AVERAGEIFS(EHR_Export[Staff on Duty],EHR_Export[Department Full Name],Dashboard_Calculator!K13,EHR_Export[Shift Type],N$8) -> 2.5
J15: Visits | K15: Department | L15: Day | M15: Evening | N15: Night
A16: Treatment Time vs Satisfaction Score (Combo Chart) | E16: Wait Time vs Satisfaction Score (Scatterplot) | K16: Cardiology | L16: =COUNTIFS(EHR_Export[Shift Type],Dashboard_Calculator!L$15,EHR_Export[Department Full Name],Dashboard_Calculator!$K16) -> 52 | M16: =COUNTIFS(EHR_Export[Shift Type],Dashboard_Calculator!M$15,EHR_Export[Department Full Name],Dashboard_Calculator!$K16) -> 62 | N16: =COUNTIFS(EHR_Export[Shift Type],Dashboard_Calculator!N$15,EHR_Export[Department Full Name],Dashboard_Calculator!$K16) -> 11
A17: Row Labels | B17: Average of Treatment Time (min) | C17: Average of Satisfaction (1-5) | E17: CARD (Day) | F17: 37.942308 | G17: 3.7227273 | K17: Emergency | L17: =COUNTIFS(EHR_Export[Shift Type],Dashboard_Calculator!L$15,EHR_Export[Department Full Name],Dashboard_Calculator!$K17) -> 143 | M17: =COUNTIFS(EHR_Export[Shift Type],Dashboard_Calculator!M$15,EHR_Export[Department Full Name],Dashboard_Calculator!$K17) -> 149 | N17: =COUNTIFS(EHR_Export[Shift Type],Dashboard_Calculator!N$15,EHR_Export[Department Full Name],Dashboard_Calculator!$K17) -> 23
A18: CARD | E18: CARD (Evening) | F18: 48.209677 | G18: 3.4581818 | K18: General Surgery | L18: =COUNTIFS(EHR_Export[Shift Type],Dashboard_Calculator!L$15,EHR_Export[Department Full Name],Dashboard_Calculator!$K18) -> 58 | M18: =COUNTIFS(EHR_Export[Shift Type],Dashboard_Calculator!M$15,EHR_Export[Department Full Name],Dashboard_Calculator!$K18) -> 59 | N18: =COUNTIFS(EHR_Export[Shift Type],Dashboard_Calculator!N$15,EHR_Export[Department Full Name],Dashboard_Calculator!$K18) -> 10
A19: Day | B19: 43.403846 | C19: 3.7227273 | E19: CARD (Night) | F19: 35.909091 | G19: 4.1875 | K19: Orthopedics | L19: =COUNTIFS(EHR_Export[Shift Type],Dashboard_Calculator!L$15,EHR_Export[Department Full Name],Dashboard_Calculator!$K19) -> 46 | M19: =COUNTIFS(EHR_Export[Shift Type],Dashboard_Calculator!M$15,EHR_Export[Department Full Name],Dashboard_Calculator!$K19) -> 54 | N19: =COUNTIFS(EHR_Export[Shift Type],Dashboard_Calculator!N$15,EHR_Export[Department Full Name],Dashboard_Calculator!$K19) -> 11
A20: Evening | B20: 43.467742 | C20: 3.4581818 | E20: ER (Day) | F20: 48.307692 | G20: 3.5333333 | K20: Pediatrics | L20: =COUNTIFS(EHR_Export[Shift Type],Dashboard_Calculator!L$15,EHR_Export[Department Full Name],Dashboard_Calculator!$K20) -> 57 | M20: =COUNTIFS(EHR_Export[Shift Type],Dashboard_Calculator!M$15,EHR_Export[Department Full Name],Dashboard_Calculator!$K20) -> 67 | N20: =COUNTIFS(EHR_Export[Shift Type],Dashboard_Calculator!N$15,EHR_Export[Department Full Name],Dashboard_Calculator!$K20) -> 14
A21: Night | B21: 45.454545 | C21: 4.1875 | E21: ER (Evening) | F21: 62.758389 | G21: 3.3962406
A22: ER | E22: ER (Night) | F22: 49.304348 | G22: 3.5782609
A23: Day | B23: 37.244755 | C23: 3.5333333 | E23: ORTH (Day) | F23: 52.521739 | G23: 3.2930233
A24: Evening | B24: 42.268456 | C24: 3.3962406 | E24: ORTH (Evening) | F24: 76.351852 | G24: 3.2634615
A25: Night | B25: 39.608696 | C25: 3.5782609 | E25: ORTH (Night) | F25: 52.272727 | G25: 3.5545455
A26: ORTH | E26: PEDS (Day) | F26: 33.824561 | G26: 3.8425926
A27: Day | B27: 37.782609 | C27: 3.2930233 | E27: PEDS (Evening) | F27: 43.149254 | G27: 3.7032787
A28: Evening | B28: 41.62963 | C28: 3.2634615 | E28: PEDS (Night) | F28: 33.642857 | G28: 3.7785714
A29: Night | B29: 43.818182 | C29: 3.5545455 | E29: SURG (Day) | F29: 58.431034 | G29: 3.425
A30: PEDS | E30: SURG (Evening) | F30: 81.40678 | G30: 2.9553571
A31: Day | B31: 40.666667 | C31: 3.8425926 | E31: SURG (Night) | F31: 64.4 | G31: 3.48
A32: Evening | B32: 41.716418 | C32: 3.7032787
A33: Night | B33: 38.571429 | C33: 3.7785714
A34: SURG
A35: Day | B35: 90.155172 | C35: 3.425
A36: Evening | B36: 88.525424 | C36: 2.9553571
A37: Night | B37: 90.2 | C37: 3.48
A38: Grand Total | B38: 48.360294 | C38: 3.4794393

Sheet Dashboard
A1: Patient Satisfaction and Hospital Cost Performance (Q1 2026)
D29: Department Performance Summary
D32: Department | F32: Average Wait Time (min) | I32: Average Treatment Time (min) | L32: Average Satisfaction | O32: Versus 3.8 Target | Q32: Average Charge | S32: Average Base Cost | U32: Over/Under Base Cost | Y32: Readmission Rate
D33: =Dashboard_Calculator!A2 -> Cardiology | F33: =Dashboard_Calculator!B2 -> 42.856 | I33: =Dashboard_Calculator!C2 -> 43.616 | L33: =Dashboard_Calculator!D2 -> 3.6214953 | O33: =Dashboard_Calculator!E2 -> -0.17850467 | Q33: =Dashboard_Calculator!F2 -> 1763.0102 | S33: =Dashboard_Calculator!G2 -> 1800 | U33: =Dashboard_Calculator!H2 -> -36.989836 | Y33: =Dashboard_Calculator!I2 -> 0.088
D34: =Dashboard_Calculator!A3 -> Emergency | F34: =Dashboard_Calculator!B3 -> 55.215873 | I34: =Dashboard_Calculator!C3 -> 39.793651 | L34: =Dashboard_Calculator!D3 -> 3.4729825 | O34: =Dashboard_Calculator!E3 -> -0.32701754 | Q34: =Dashboard_Calculator!F3 -> 852.69323 | S34: =Dashboard_Calculator!G3 -> 850 | U34: =Dashboard_Calculator!H3 -> 2.6932258 | Y34: =Dashboard_Calculator!I3 -> 0.088888889
D35: =Dashboard_Calculator!A4 -> General Surgery | F35: =Dashboard_Calculator!B4 -> 69.574803 | I35: =Dashboard_Calculator!C4 -> 89.401575 | L35: =Dashboard_Calculator!D4 -> 3.2139344 | O35: =Dashboard_Calculator!E4 -> -0.58606557 | Q35: =Dashboard_Calculator!F4 -> 3239.2171 | S35: =Dashboard_Calculator!G4 -> 3200 | U35: =Dashboard_Calculator!H4 -> 39.21712 | Y35: =Dashboard_Calculator!I4 -> 0.11023622
D36: =Dashboard_Calculator!A5 -> Orthopedics | F36: =Dashboard_Calculator!B5 -> 64.09009 | I36: =Dashboard_Calculator!C5 -> 40.252252 | L36: =Dashboard_Calculator!D5 -> 3.3056604 | O36: =Dashboard_Calculator!E5 -> -0.49433962 | Q36: =Dashboard_Calculator!F5 -> 1507.6381 | S36: =Dashboard_Calculator!G5 -> 1500 | U36: =Dashboard_Calculator!H5 -> 7.6381481 | Y36: =Dashboard_Calculator!I5 -> 0.09009009
D37: =Dashboard_Calculator!A6 -> Pediatrics | F37: =Dashboard_Calculator!B6 -> 38.333333 | I37: =Dashboard_Calculator!C6 -> 40.963768 | L37: =Dashboard_Calculator!D6 -> 3.7697674 | O37: =Dashboard_Calculator!E6 -> -0.030232558 | Q37: =Dashboard_Calculator!F6 -> 697.87679 | S37: =Dashboard_Calculator!G6 -> 700 | U37: =Dashboard_Calculator!H6 -> -2.1232117 | Y37: =Dashboard_Calculator!I6 -> 0.12318841
